Workbook

Sheet Parameters
A1: Parameter | B1: Value
A2: Fair Value | B2: 100
A3: Half Spread | B3: 1
A4: Inventory Sensitivity k | B4: 0.25
A5: Starting Cash | B5: 0
A6: Starting Inventory | B6: 0
A7: Customer Sensitivity a | B7: 0.2
A8: Price Move Size | B8: 1
A9: Inventory Limit | B9: 5
A10: Spread Sensitivity b | B10: 0.25

Sheet Trades
A1: Trade | B1: Order | C1: Fair Value | D1: Price Move | E1: Inventory Before | F1: Quote Centre | G1: Bid | H1: Ask | I1: Execution Price | J1: Cash After | K1: Inventory After | L1: PnL | M1: Buy Probability | N1: Order Random Draw | O1: Price Random Draw | P1: Trade Status | Q1: Trade Probability | R1: Trade Random Draw
A2: 1 | B2: =IF(N2<M2,"BUY","SELL") -> SELL | C2: =Parameters!$B$2 -> 100 | D2: =0 -> 0 | E2: =Parameters!$B$6 -> 0 | F2: =C2-Parameters!$B$4*E2 -> 100 | G2: =F2-Parameters!$B$3 -> 99 | H2: =F2+Parameters!$B$3 -> 101 | I2: =IF(P2<>"EXECUTED","",IF(B2="SELL",G2,H2)) | J2: =IF(P2<>"EXECUTED",Parameters!$B$5,IF(B2="SELL",Parameters!$B$5-I2,Parameters!$B$5+I2)) -> 0 | K2: =IF(P2<>"EXECUTED",E2,IF(B2="SELL",E2+1,E2-1)) -> 0 | L2: =J2+K2*C2 -> 0 | M2: =MAX(0.05,MIN(0.95,0.5+Parameters!$B$7*(C2-F2))) -> 0.5 | N2: 0.5681716 | P2: =IF(R2>Q2,"NO TRADE",IF(OR(AND(B2="SELL",E2>=Parameters!$B$9),AND(B2="BUY",E2<=-Parameters!$B$9)),"REJECTED","EXECUTED")) -> NO TRADE | Q2: =MAX(0.05,MIN(0.95,1-Parameters!$B$10*Parameters!$B$3)) -> 0.75 | R2: =RAND() -> 0.92416332
A3: =A2+1 -> 2 | B3: =IF(N3<M3,"BUY","SELL") -> SELL | C3: =C2+D3 -> 101 | D3: =IF(O3<0.5,-Parameters!$B$8,Parameters!$B$8) -> 1 | E3: =K2 -> 0 | F3: =C3-Parameters!$B$4*E3 -> 101 | G3: =F3-Parameters!$B$3 -> 100 | H3: =F3+Parameters!$B$3 -> 102 | I3: =IF(P3<>"EXECUTED","",IF(B3="SELL",G3,H3)) -> 100 | J3: =IF(P3<>"EXECUTED",J2,IF(B3="SELL",J2-I3,J2+I3)) -> -100 | K3: =IF(P3<>"EXECUTED",E3,IF(B3="SELL",E3+1,E3-1)) -> 1 | L3: =J3+K3*C3 -> 1 | M3: =MAX(0.05,MIN(0.95,0.5+Parameters!$B$7*(C3-F3))) -> 0.5 | N3: 0.74168005 | O3: 0.88197187 | P3: =IF(R3>Q3,"NO TRADE",IF(OR(AND(B3="SELL",E3>=Parameters!$B$9),AND(B3="BUY",E3<=-Parameters!$B$9)),"REJECTED","EXECUTED")) -> EXECUTED | Q3: =MAX(0.05,MIN(0.95,1-Parameters!$B$10*Parameters!$B$3)) -> 0.75 | R3: =RAND() -> 0.24064145
A4: =A3+1 -> 3 | B4: =IF(N4<M4,"BUY","SELL") -> SELL | C4: =C3+D4 -> 100 | D4: =IF(O4<0.5,-Parameters!$B$8,Parameters!$B$8) -> -1 | E4: =K3 -> 1 | F4: =C4-Parameters!$B$4*E4 -> 99.75 | G4: =F4-Parameters!$B$3 -> 98.75 | H4: =F4+Parameters!$B$3 -> 100.75 | I4: =IF(P4<>"EXECUTED","",IF(B4="SELL",G4,H4)) -> 98.75 | J4: =IF(P4<>"EXECUTED",J3,IF(B4="SELL",J3-I4,J3+I4)) -> -198.75 | K4: =IF(P4<>"EXECUTED",E4,IF(B4="SELL",E4+1,E4-1)) -> 2 | L4: =J4+K4*C4 -> 1.25 | M4: =MAX(0.05,MIN(0.95,0.5+Parameters!$B$7*(C4-F4))) -> 0.55 | N4: 0.77324211 | O4: 0.33743301 | P4: =IF(R4>Q4,"NO TRADE",IF(OR(AND(B4="SELL",E4>=Parameters!$B$9),AND(B4="BUY",E4<=-Parameters!$B$9)),"REJECTED","EXECUTED")) -> EXECUTED | Q4: =MAX(0.05,MIN(0.95,1-Parameters!$B$10*Parameters!$B$3)) -> 0.75 | R4: =RAND() -> 0.56196477
A5: =A4+1 -> 4 | B5: =IF(N5<M5,"BUY","SELL") -> BUY | C5: =C4+D5 -> 99 | D5: =IF(O5<0.5,-Parameters!$B$8,Parameters!$B$8) -> -1 | E5: =K4 -> 2 | F5: =C5-Parameters!$B$4*E5 -> 98.5 | G5: =F5-Parameters!$B$3 -> 97.5 | H5: =F5+Parameters!$B$3 -> 99.5 | I5: =IF(P5<>"EXECUTED","",IF(B5="SELL",G5,H5)) -> 99.5 | J5: =IF(P5<>"EXECUTED",J4,IF(B5="SELL",J4-I5,J4+I5)) -> -99.25 | K5: =IF(P5<>"EXECUTED",E5,IF(B5="SELL",E5+1,E5-1)) -> 1 | L5: =J5+K5*C5 -> -0.25 | M5: =MAX(0.05,MIN(0.95,0.5+Parameters!$B$7*(C5-F5))) -> 0.6 | N5: 0.49189413 | O5: 0.36166166 | P5: =IF(R5>Q5,"NO TRADE",IF(OR(AND(B5="SELL",E5>=Parameters!$B$9),AND(B5="BUY",E5<=-Parameters!$B$9)),"REJECTED","EXECUTED")) -> EXECUTED | Q5: =MAX(0.05,MIN(0.95,1-Parameters!$B$10*Parameters!$B$3)) -> 0.75 | R5: =RAND() -> 0.3211576
A6: =A5+1 -> 5 | B6: =IF(N6<M6,"BUY","SELL") -> SELL | C6: =C5+D6 -> 100 | D6: =IF(O6<0.5,-Parameters!$B$8,Parameters!$B$8) -> 1 | E6: =K5 -> 1 | F6: =C6-Parameters!$B$4*E6 -> 99.75 | G6: =F6-Parameters!$B$3 -> 98.75 | H6: =F6+Parameters!$B$3 -> 100.75 | I6: =IF(P6<>"EXECUTED","",IF(B6="SELL",G6,H6)) -> 98.75 | J6: =IF(P6<>"EXECUTED",J5,IF(B6="SELL",J5-I6,J5+I6)) -> -198 | K6: =IF(P6<>"EXECUTED",E6,IF(B6="SELL",E6+1,E6-1)) -> 2 | L6: =J6+K6*C6 -> 2 | M6: =MAX(0.05,MIN(0.95,0.5+Parameters!$B$7*(C6-F6))) -> 0.55 | N6: 0.99836901 | O6: 0.67598594 | P6: =IF(R6>Q6,"NO TRADE",IF(OR(AND(B6="SELL",E6>=Parameters!$B$9),AND(B6="BUY",E6<=-Parameters!$B$9)),"REJECTED","EXECUTED")) -> EXECUTED | Q6: =MAX(0.05,MIN(0.95,1-Parameters!$B$10*Parameters!$B$3)) -> 0.75 | R6: =RAND() -> 0.25268099
A7: =A6+1 -> 6 | B7: =IF(N7<M7,"BUY","SELL") -> BUY | C7: =C6+D7 -> 99 | D7: =IF(O7<0.5,-Parameters!$B$8,Parameters!$B$8) -> -1 | E7: =K6 -> 2 | F7: =C7-Parameters!$B$4*E7 -> 98.5 | G7: =F7-Parameters!$B$3 -> 97.5 | H7: =F7+Parameters!$B$3 -> 99.5 | I7: =IF(P7<>"EXECUTED","",IF(B7="SELL",G7,H7)) | J7: =IF(P7<>"EXECUTED",J6,IF(B7="SELL",J6-I7,J6+I7)) -> -198 | K7: =IF(P7<>"EXECUTED",E7,IF(B7="SELL",E7+1,E7-1)) -> 2 | L7: =J7+K7*C7 -> 0 | M7: =MAX(0.05,MIN(0.95,0.5+Parameters!$B$7*(C7-F7))) -> 0.6 | N7: 0.10290689 | O7: 0.24550919 | P7: =IF(R7>Q7,"NO TRADE",IF(OR(AND(B7="SELL",E7>=Parameters!$B$9),AND(B7="BUY",E7<=-Parameters!$B$9)),"REJECTED","EXECUTED")) -> NO TRADE | Q7: =MAX(0.05,MIN(0.95,1-Parameters!$B$10*Parameters!$B$3)) -> 0.75 | R7: =RAND() -> 0.77338634
A8: =A7+1 -> 7 | B8: =IF(N8<M8,"BUY","SELL") -> SELL | C8: =C7+D8 -> 100 | D8: =IF(O8<0.5,-Parameters!$B$8,Parameters!$B$8) -> 1 | E8: =K7 -> 2 | F8: =C8-Parameters!$B$4*E8 -> 99.5 | G8: =F8-Parameters!$B$3 -> 98.5 | H8: =F8+Parameters!$B$3 -> 100.5 | I8: =IF(P8<>"EXECUTED","",IF(B8="SELL",G8,H8)) -> 98.5 | J8: =IF(P8<>"EXECUTED",J7,IF(B8="SELL",J7-I8,J7+I8)) -> -296.5 | K8: =IF(P8<>"EXECUTED",E8,IF(B8="SELL",E8+1,E8-1)) -> 3 | L8: =J8+K8*C8 -> 3.5 | M8: =MAX(0.05,MIN(0.95,0.5+Parameters!$B$7*(C8-F8))) -> 0.6 | N8: 0.9318899 | O8: 0.52098037 | P8: =IF(R8>Q8,"NO TRADE",IF(OR(AND(B8="SELL",E8>=Parameters!$B$9),AND(B8="BUY",E8<=-Parameters!$B$9)),"REJECTED","EXECUTED")) -> EXECUTED | Q8: =MAX(0.05,MIN(0.95,1-Parameters!$B$10*Parameters!$B$3)) -> 0.75 | R8: =RAND() -> 0.64411271
A9: =A8+1 -> 8 | B9: =IF(N9<M9,"BUY","SELL") -> SELL | C9: =C8+D9 -> 101 | D9: =IF(O9<0.5,-Parameters!$B$8,Parameters!$B$8) -> 1 | E9: =K8 -> 3 | F9: =C9-Parameters!$B$4*E9 -> 100.25 | G9: =F9-Parameters!$B$3 -> 99.25 | H9: =F9+Parameters!$B$3 -> 101.25 | I9: =IF(P9<>"EXECUTED","",IF(B9="SELL",G9,H9)) -> 99.25 | J9: =IF(P9<>"EXECUTED",J8,IF(B9="SELL",J8-I9,J8+I9)) -> -395.75 | K9: =IF(P9<>"EXECUTED",E9,IF(B9="SELL",E9+1,E9-1)) -> 4 | L9: =J9+K9*C9 -> 8.25 | M9: =MAX(0.05,MIN(0.95,0.5+Parameters!$B$7*(C9-F9))) -> 0.65 | N9: 0.99516678 | O9: 0.82195716 | P9: =IF(R9>Q9,"NO TRADE",IF(OR(AND(B9="SELL",E9>=Parameters!$B$9),AND(B9="BUY",E9<=-Parameters!$B$9)),"REJECTED","EXECUTED")) -> EXECUTED | Q9: =MAX(0.05,MIN(0.95,1-Parameters!$B$10*Parameters!$B$3)) -> 0.75 | R9: =RAND() -> 0.35267707
A10: =A9+1 -> 9 | B10: =IF(N10<M10,"BUY","SELL") -> BUY | C10: =C9+D10 -> 100 | D10: =IF(O10<0.5,-Parameters!$B$8,Parameters!$B$8) -> -1 | E10: =K9 -> 4 | F10: =C10-Parameters!$B$4*E10 -> 99 | G10: =F10-Parameters!$B$3 -> 98 | H10: =F10+Parameters!$B$3 -> 100 | I10: =IF(P10<>"EXECUTED","",IF(B10="SELL",G10,H10)) -> 100 | J10: =IF(P10<>"EXECUTED",J9,IF(B10="SELL",J9-I10,J9+I10)) -> -295.75 | K10: =IF(P10<>"EXECUTED",E10,IF(B10="SELL",E10+1,E10-1)) -> 3 | L10: =J10+K10*C10 -> 4.25 | M10: =MAX(0.05,MIN(0.95,0.5+Parameters!$B$7*(C10-F10))) -> 0.7 | N10: 0.60738987 | O10: 0.060462993 | P10: =IF(R10>Q10,"NO TRADE",IF(OR(AND(B10="SELL",E10>=Parameters!$B$9),AND(B10="BUY",E10<=-Parameters!$B$9)),"REJECTED","EXECUTED")) -> EXECUTED | Q10: =MAX(0.05,MIN(0.95,1-Parameters!$B$10*Parameters!$B$3)) -> 0.75 | R10: =RAND() -> 0.25038238
A11: =A10+1 -> 10 | B11: =IF(N11<M11,"BUY","SELL") -> BUY | C11: =C10+D11 -> 101 | D11: =IF(O11<0.5,-Parameters!$B$8,Parameters!$B$8) -> 1 | E11: =K10 -> 3 | F11: =C11-Parameters!$B$4*E11 -> 100.25 | G11: =F11-Parameters!$B$3 -> 99.25 | H11: =F11+Parameters!$B$3 -> 101.25 | I11: =IF(P11<>"EXECUTED","",IF(B11="SELL",G11,H11)) -> 101.25 | J11: =IF(P11<>"EXECUTED",J10,IF(B11="SELL",J10-I11,J10+I11)) -> -194.5 | K11: =IF(P11<>"EXECUTED",E11,IF(B11="SELL",E11+1,E11-1)) -> 2 | L11: =J11+K11*C11 -> 7.5 | M11: =MAX(0.05,MIN(0.95,0.5+Parameters!$B$7*(C11-F11))) -> 0.65 | N11: 0.64514694 | O11: 0.53736941 | P11: =IF(R11>Q11,"NO TRADE",IF(OR(AND(B11="SELL",E11>=Parameters!$B$9),AND(B11="BUY",E11<=-Parameters!$B$9)),"REJECTED","EXECUTED")) -> EXECUTED | Q11: =MAX(0.05,MIN(0.95,1-Parameters!$B$10*Parameters!$B$3)) -> 0.75 | R11: =RAND() -> 0.050335069
A12: =A11+1 -> 11 | B12: =IF(N12<M12,"BUY","SELL") -> BUY | C12: =C11+D12 -> 102 | D12: =IF(O12<0.5,-Parameters!$B$8,Parameters!$B$8) -> 1 | E12: =K11 -> 2 | F12: =C12-Parameters!$B$4*E12 -> 101.5 | G12: =F12-Parameters!$B$3 -> 100.5 | H12: =F12+Parameters!$B$3 -> 102.5 | I12: =IF(P12<>"EXECUTED","",IF(B12="SELL",G12,H12)) -> 102.5 | J12: =IF(P12<>"EXECUTED",J11,IF(B12="SELL",J11-I12,J11+I12)) -> -92 | K12: =IF(P12<>"EXECUTED",E12,IF(B12="SELL",E12+1,E12-1)) -> 1 | L12: =J12+K12*C12 -> 10 | M12: =MAX(0.05,MIN(0.95,0.5+Parameters!$B$7*(C12-F12))) -> 0.6 | N12: 0.30264633 | O12: 0.59427334 | P12: =IF(R12>Q12,"NO TRADE",IF(OR(AND(B12="SELL",E12>=Parameters!$B$9),AND(B12="BUY",E12<=-Parameters!$B$9)),"REJECTED","EXECUTED")) -> EXECUTED | Q12: =MAX(0.05,MIN(0.95,1-Parameters!$B$10*Parameters!$B$3)) -> 0.75 | R12: =RAND() -> 0.72230503
A13: =A12+1 -> 12 | B13: =IF(N13<M13,"BUY","SELL") -> SELL | C13: =C12+D13 -> 101 | D13: =IF(O13<0.5,-Parameters!$B$8,Parameters!$B$8) -> -1 | E13: =K12 -> 1 | F13: =C13-Parameters!$B$4*E13 -> 100.75 | G13: =F13-Parameters!$B$3 -> 99.75 | H13: =F13+Parameters!$B$3 -> 101.75 | I13: =IF(P13<>"EXECUTED","",IF(B13="SELL",G13,H13)) -> 99.75 | J13: =IF(P13<>"EXECUTED",J12,IF(B13="SELL",J12-I13,J12+I13)) -> -191.75 | K13: =IF(P13<>"EXECUTED",E13,IF(B13="SELL",E13+1,E13-1)) -> 2 | L13: =J13+K13*C13 -> 10.25 | M13: =MAX(0.05,MIN(0.95,0.5+Parameters!$B$7*(C13-F13))) -> 0.55 | N13: 0.78305914 | O13: 0.098288778 | P13: =IF(R13>Q13,"NO TRADE",IF(OR(AND(B13="SELL",E13>=Parameters!$B$9),AND(B13="BUY",E13<=-Parameters!$B$9)),"REJECTED","EXECUTED")) -> EXECUTED | Q13: =MAX(0.05,MIN(0.95,1-Parameters!$B$10*Parameters!$B$3)) -> 0.75 | R13: =RAND() -> 0.25107773
A14: =A13+1 -> 13 | B14: =IF(N14<M14,"BUY","SELL") -> SELL | C14: =C13+D14 -> 102 | D14: =IF(O14<0.5,-Parameters!$B$8,Parameters!$B$8) -> 1 | E14: =K13 -> 2 | F14: =C14-Parameters!$B$4*E14 -> 101.5 | G14: =F14-Parameters!$B$3 -> 100.5 | H14: =F14+Parameters!$B$3 -> 102.5 | I14: =IF(P14<>"EXECUTED","",IF(B14="SELL",G14,H14)) -> 100.5 | J14: =IF(P14<>"EXECUTED",J13,IF(B14="SELL",J13-I14,J13+I14)) -> -292.25 | K14: =IF(P14<>"EXECUTED",E14,IF(B14="SELL",E14+1,E14-1)) -> 3 | L14: =J14+K14*C14 -> 13.75 | M14: =MAX(0.05,MIN(0.95,0.5+Parameters!$B$7*(C14-F14))) -> 0.6 | N14: 0.93812006 | O14: 0.97406023 | P14: =IF(R14>Q14,"NO TRADE",IF(OR(AND(B14="SELL",E14>=Parameters!$B$9),AND(B14="BUY",E14<=-Parameters!$B$9)),"REJECTED","EXECUTED")) -> EXECUTED | Q14: =MAX(0.05,MIN(0.95,1-Parameters!$B$10*Parameters!$B$3)) -> 0.75 | R14: =RAND() -> 0.64348579
... A21: =A20+1 -> 20 | B21: =IF(N21<M21,"BUY","SELL") -> SELL | C21: =C20+D21 -> 101 | D21: =IF(O21<0.5,-Parameters!$B$8,Parameters!$B$8) -> 1 | E21: =K20 -> 4 | F21: =C21-Parameters!$B$4*E21 -> 100 | G21: =F21-Parameters!$B$3 -> 99 | H21: =F21+Parameters!$B$3 -> 101 | I21: =IF(P21<>"EXECUTED","",IF(B21="SELL",G21,H21)) -> 99 | J21: =IF(P21<>"EXECUTED",J20,IF(B21="SELL",J20-I21,J20+I21)) -> -485 | K21: =IF(P21<>"EXECUTED",E21,IF(B21="SELL",E21+1,E21-1)) -> 5 | L21: =J21+K21*C21 -> 20 | M21: =MAX(0.05,MIN(0.95,0.5+Parameters!$B$7*(C21-F21))) -> 0.7 | N21: 0.96663361 | O21: 0.70180745 | P21: =IF(R21>Q21,"NO TRADE",IF(OR(AND(B21="SELL",E21>=Parameters!$B$9),AND(B21="BUY",E21<=-Parameters!$B$9)),"REJECTED","EXECUTED")) -> EXECUTED | Q21: =MAX(0.05,MIN(0.95,1-Parameters!$B$10*Parameters!$B$3)) -> 0.75 | R21: =RAND() -> 0.089414755
A22: =A21+1 -> 21 | C22: =Parameters!$B$2 -> 100 | E22: =IF(B22="","",K21) | F22: =IF(B22="","",C22-Parameters!$B$4*E22) | G22: =IF(B22="","",F22-Parameters!$B$3) | H22: =IF(B22="","",F22+Parameters!$B$3) | I22: =IF(B22="","",IF(B22="SELL",G22,H22)) | J22: =IF(B22="","",IF(B22="SELL",J21-I22,J21+I22)) | K22: =IF(B22="","",IF(B22="SELL",E22+1,E22-1)) | L22: =IF(B22="","",J22+K22*C22)

Sheet Experiments
A1: Strategy | B1: k | C1: Final PnL | D1: Max Abs Inventory | E1: Final Abs Inventory
A2: Inventory-Aware | B2: 0.25 | C2: 3.5 | D2: 4 | E2: 4
A3: Baseline | B3: 0 | C3: 4 | D3: 4 | E3: 4
A5: Day 10: one 20-trade run per strategy, captured as fixed values.
A6: Both runs use the same realized price moves and random draws.
A7: Trades remains live; recalculation does not change the results above.
A8: One run per strategy is insufficient to establish which is better.
A10: Controlled Comparison — Same Random Draws
A12: Strategy | B12: k | C12: Final PnL | D12: Max Abs Inventory | E12: Final Abs Inventory
A13: Inventory-Aware | B13: 0.25 | C13: 14 | D13: 4 | E13: 2
A14: Baseline | B14: 0 | C14: 18 | D14: 4 | E14: 4
A16: Day 11: one controlled 20-trade scenario; results captured as fixed values.
A17: Frozen inputs: Trades!N2:N21 (orders) and O3:O21 (prices). Only k differs.
A18: Orders, probabilities, quotes, inventory and PnL remain formulas.
A19: One controlled scenario does not establish general superiority.
A21: Repeated Controlled Trials
A22: 10 scenarios, 20 trades per strategy. IA = Inventory-Aware (k = 0.25); Baseline k = 0.
A23: Trial | B23: IA Final PnL | C23: IA Max Abs Inventory | D23: IA Final Abs Inventory | E23: Baseline Final PnL | F23: Baseline Max Abs Inventory | G23: Baseline Final Abs Inventory
A24: 1 | B24: 14 | C24: 4 | D24: 2 | E24: 18 | F24: 4 | G24: 4
A25: 2 | B25: 17.5 | C25: 3 | D25: 0 | E25: 12 | F25: 4 | G25: 2
A26: 3 | B26: -2 | C26: 4 | D26: 2 | E26: 0 | F26: 4 | G26: 2
A27: 4 | B27: 18 | C27: 2 | D27: 2 | E27: 20 | F27: 2 | G27: 2
A28: 5 | B28: 28 | C28: 4 | D28: 2 | E28: 30 | F28: 4 | G28: 2
A29: 6 | B29: 16 | C29: 3 | D29: 2 | E29: 18 | F29: 4 | G29: 4
A30: 7 | B30: 19.5 | C30: 4 | D30: 0 | E30: 18 | F30: 4 | G30: 0
A31: 8 | B31: 20 | C31: 3 | D31: 2 | E31: 20 | F31: 3 | G31: 0
A32: 9 | B32: 25.5 | C32: 2 | D32: 0 | E32: 12 | F32: 4 | G32: 2
A33: 10 | B33: 19.5 | C33: 4 | D33: 4 | E33: 22 | F33: 10 | G33: 10
A35: AVERAGE | B35: =AVERAGE(B24:B33) -> 17.6 | C35: =AVERAGE(C24:C33) -> 3.3 | D35: =AVERAGE(D24:D33) -> 1.6 | E35: =AVERAGE(E24:E33) -> 17 | F35: =AVERAGE(F24:F33) -> 4.3 | G35: =AVERAGE(G24:G33) -> 2.8
A36: WORST | B36: =MIN(B24:B33) -> -2 | E36: =MIN(E24:E33) -> 0
A38: Average PnL Difference (IA - Baseline) | E38: =B35-E35 -> 0.6
A39: Average Max Inventory Difference (IA - Baseline) | E39: =C35-F35 -> -1
A41: Trial 1 reuses Day 11. Trials 2–10 use nine fresh, independently generated scenarios.
A42: All trial results are fixed values. Trades is left on Trial 10 with k = 0.25.
A43: WORST reports the lowest PnL observed in these ten trials, not a theoretical worst case.
A44: Frozen inputs for every trial are retained below so each comparison can be reproduced.
A47: Frozen Scenario Inputs
A48: To replay: copy a trial’s order draws to Trades!N2:N21 and price draws for trades 2–20 to O3:O21.
A49: Trial | B49: Trade | C49: Order Random Draw | D49: Price Random Draw
A50: 1 | B50: 1 | C50: 0.86531313
...
